2020-07-16 14:02:18,359 INFO: Microblog startup [in C:\Dev\FlaskMegaTutorial\app\__init__.py:47]
2020-07-16 14:02:31,606 INFO: Microblog startup [in C:\Dev\FlaskMegaTutorial\app\__init__.py:47]
2020-07-16 14:07:56,368 INFO: Microblog startup [in C:\Dev\FlaskMegaTutorial\app\__init__.py:47]
2020-07-16 14:08:20,960 ERROR: Exception on /edit_profile [GET] [in c:\dev\flaskmegatutorial\venv\lib\site-packages\flask\app.py:1892]
Traceback (most recent call last):
  File "c:\dev\flaskmegatutorial\venv\lib\site-packages\flask\app.py", line 2447, in wsgi_app
    response = self.full_dispatch_request()
  File "c:\dev\flaskmegatutorial\venv\lib\site-packages\flask\app.py", line 1952, in full_dispatch_request
    rv = self.handle_user_exception(e)
  File "c:\dev\flaskmegatutorial\venv\lib\site-packages\flask\app.py", line 1821, in handle_user_exception
    reraise(exc_type, exc_value, tb)
  File "c:\dev\flaskmegatutorial\venv\lib\site-packages\flask\_compat.py", line 39, in reraise
    raise value
  File "c:\dev\flaskmegatutorial\venv\lib\site-packages\flask\app.py", line 1950, in full_dispatch_request
    rv = self.dispatch_request()
  File "c:\dev\flaskmegatutorial\venv\lib\site-packages\flask\app.py", line 1936, in dispatch_request
    return self.view_functions[rule.endpoint](**req.view_args)
  File "c:\dev\flaskmegatutorial\venv\lib\site-packages\flask_login\utils.py", line 272, in decorated_view
    return func(*args, **kwargs)
  File "C:\Dev\FlaskMegaTutorial\app\routes.py", line 86, in edit_profile
    form = EditProfileForm(current_user.username)
  File "c:\dev\flaskmegatutorial\venv\lib\site-packages\wtforms\form.py", line 208, in __call__
    return type.__call__(cls, *args, **kwargs)
  File "C:\Dev\FlaskMegaTutorial\app\forms.py", line 36, in __init__
    super(EditProfileForm, self).__init__(*ags, **kwargs)
NameError: name 'ags' is not defined
2020-07-17 11:47:44,589 INFO: Microblog startup [in C:\Dev\FlaskMegaTutorial\app\__init__.py:47]
2020-07-17 12:06:55,109 INFO: Microblog startup [in C:\Dev\FlaskMegaTutorial\app\__init__.py:47]
2020-07-17 12:07:59,649 INFO: Microblog startup [in C:\Dev\FlaskMegaTutorial\app\__init__.py:47]
2020-07-17 12:09:54,780 INFO: Microblog startup [in C:\Dev\FlaskMegaTutorial\app\__init__.py:47]
2020-07-17 12:11:29,398 INFO: Microblog startup [in C:\Dev\FlaskMegaTutorial\app\__init__.py:47]
2020-07-17 12:14:19,777 INFO: Microblog startup [in C:\Dev\FlaskMegaTutorial\app\__init__.py:47]
2020-07-17 13:07:31,473 INFO: Microblog startup [in C:\Dev\FlaskMegaTutorial\app\__init__.py:47]
2020-07-17 13:07:47,655 ERROR: Exception on /user/susan [GET] [in c:\dev\flaskmegatutorial\venv\lib\site-packages\flask\app.py:1892]
Traceback (most recent call last):
  File "c:\dev\flaskmegatutorial\venv\lib\site-packages\sqlalchemy\engine\base.py", line 1278, in _execute_context
    cursor, statement, parameters, context
  File "c:\dev\flaskmegatutorial\venv\lib\site-packages\sqlalchemy\engine\default.py", line 593, in do_execute
    cursor.execute(statement, parameters)
sqlite3.OperationalError: no such table: followers

The above exception was the direct cause of the following exception:

Traceback (most recent call last):
  File "c:\dev\flaskmegatutorial\venv\lib\site-packages\flask\app.py", line 2447, in wsgi_app
    response = self.full_dispatch_request()
  File "c:\dev\flaskmegatutorial\venv\lib\site-packages\flask\app.py", line 1952, in full_dispatch_request
    rv = self.handle_user_exception(e)
  File "c:\dev\flaskmegatutorial\venv\lib\site-packages\flask\app.py", line 1821, in handle_user_exception
    reraise(exc_type, exc_value, tb)
  File "c:\dev\flaskmegatutorial\venv\lib\site-packages\flask\_compat.py", line 39, in reraise
    raise value
  File "c:\dev\flaskmegatutorial\venv\lib\site-packages\flask\app.py", line 1950, in full_dispatch_request
    rv = self.dispatch_request()
  File "c:\dev\flaskmegatutorial\venv\lib\site-packages\flask\app.py", line 1936, in dispatch_request
    return self.view_functions[rule.endpoint](**req.view_args)
  File "c:\dev\flaskmegatutorial\venv\lib\site-packages\flask_login\utils.py", line 272, in decorated_view
    return func(*args, **kwargs)
  File "C:\Dev\FlaskMegaTutorial\app\routes.py", line 83, in user
    return render_template('user.html', user=user, posts=posts, form = form)
  File "c:\dev\flaskmegatutorial\venv\lib\site-packages\flask\templating.py", line 140, in render_template
    ctx.app,
  File "c:\dev\flaskmegatutorial\venv\lib\site-packages\flask\templating.py", line 120, in _render
    rv = template.render(context)
  File "c:\dev\flaskmegatutorial\venv\lib\site-packages\jinja2\environment.py", line 1090, in render
    self.environment.handle_exception()
  File "c:\dev\flaskmegatutorial\venv\lib\site-packages\jinja2\environment.py", line 832, in handle_exception
    reraise(*rewrite_traceback_stack(source=source))
  File "c:\dev\flaskmegatutorial\venv\lib\site-packages\jinja2\_compat.py", line 28, in reraise
    raise value.with_traceback(tb)
  File "C:\Dev\FlaskMegaTutorial\app\templates\user.html", line 1, in top-level template code
    {% extends "base.html" %}
  File "C:\Dev\FlaskMegaTutorial\app\templates\base.html", line 29, in top-level template code
    {% block content %}{% endblock %}
  File "C:\Dev\FlaskMegaTutorial\app\templates\user.html", line 11, in block "content"
    <p>{{ user.followers.count() }} followers, {{ user.followed.count() }} following.</p>
  File "c:\dev\flaskmegatutorial\venv\lib\site-packages\sqlalchemy\orm\dynamic.py", line 335, in count
    return self._clone(sess).count()
  File "c:\dev\flaskmegatutorial\venv\lib\site-packages\sqlalchemy\orm\query.py", line 3771, in count
    return self.from_self(col).scalar()
  File "c:\dev\flaskmegatutorial\venv\lib\site-packages\sqlalchemy\orm\query.py", line 3491, in scalar
    ret = self.one()
  File "c:\dev\flaskmegatutorial\venv\lib\site-packages\sqlalchemy\orm\query.py", line 3458, in one
    ret = self.one_or_none()
  File "c:\dev\flaskmegatutorial\venv\lib\site-packages\sqlalchemy\orm\query.py", line 3427, in one_or_none
    ret = list(self)
  File "c:\dev\flaskmegatutorial\venv\lib\site-packages\sqlalchemy\orm\query.py", line 3503, in __iter__
    return self._execute_and_instances(context)
  File "c:\dev\flaskmegatutorial\venv\lib\site-packages\sqlalchemy\orm\query.py", line 3528, in _execute_and_instances
    result = conn.execute(querycontext.statement, self._params)
  File "c:\dev\flaskmegatutorial\venv\lib\site-packages\sqlalchemy\engine\base.py", line 1014, in execute
    return meth(self, multiparams, params)
  File "c:\dev\flaskmegatutorial\venv\lib\site-packages\sqlalchemy\sql\elements.py", line 298, in _execute_on_connection
    return connection._execute_clauseelement(self, multiparams, params)
  File "c:\dev\flaskmegatutorial\venv\lib\site-packages\sqlalchemy\engine\base.py", line 1133, in _execute_clauseelement
    distilled_params,
  File "c:\dev\flaskmegatutorial\venv\lib\site-packages\sqlalchemy\engine\base.py", line 1318, in _execute_context
    e, statement, parameters, cursor, context
  File "c:\dev\flaskmegatutorial\venv\lib\site-packages\sqlalchemy\engine\base.py", line 1512, in _handle_dbapi_exception
    sqlalchemy_exception, with_traceback=exc_info[2], from_=e
  File "c:\dev\flaskmegatutorial\venv\lib\site-packages\sqlalchemy\util\compat.py", line 178, in raise_
    raise exception
  File "c:\dev\flaskmegatutorial\venv\lib\site-packages\sqlalchemy\engine\base.py", line 1278, in _execute_context
    cursor, statement, parameters, context
  File "c:\dev\flaskmegatutorial\venv\lib\site-packages\sqlalchemy\engine\default.py", line 593, in do_execute
    cursor.execute(statement, parameters)
sqlalchemy.exc.OperationalError: (sqlite3.OperationalError) no such table: followers
[SQL: SELECT count(*) AS count_1 
FROM (SELECT user.id AS user_id, user.username AS user_username, user.email AS user_email, user.password_hash AS user_password_hash, user.about_me AS user_about_me, user.last_seen AS user_last_seen 
FROM user, followers 
WHERE followers.followed_id = ? AND followers.follower_id = user.id) AS anon_1]
[parameters: (1,)]
(Background on this error at: http://sqlalche.me/e/13/e3q8)
